Workbook

Sheet Supuestos
A1: Supuestos — Galería Íntima (peor escenario: 148 estantes, sin Miedos ni suscripciones, con riesgo cambiario)
A3: ESTANTES Y CUOTAS
A4: Número total de estantes (físicos, a construir) | B4: 150
A5: Estantes reservados para intercambio / donación (no pagan cuota) | B5: 2
A6: Estantes disponibles para alquiler (base de ingresos) | B6: =B4-B5 -> 148
A7: Meta de preventa antes de construir e inaugurar (% de los estantes disponibles) | B7: 1
A8: Estantes meta antes de abrir (pagando) | B8: =B6*B7 -> 148
A9: Cuota mensual por estante (USD/mes) | B9: 7
A10: Modalidad de pago | B10: Anual adelantado (12 meses), única modalidad
A11: Pago adelantado por estante (USD/año) | B11: =B9*12 -> 84
A12: Tamaño del estante (alto x ancho x profundidad, cm) | B12: 35 x 50 x 35
A14: APERTURA Y CRECIMIENTO POST-APERTURA
A15: Tasa de renovación anual (%) | B15: 0.85
A16: Estantes nuevos por mes tras una salida (crecimiento) | B16: 5
A18: COSTOS FIJOS MENSUALES (USD)
A19: Alquiler | B19: 220
A20: Electricidad | B20: 40
A21: Internet | B21: 16
A22: Agua | B22: 10
A23: Publicidad | B23: 10
A24: Limpieza | B24: 30
A25: Mantenimiento del sitio web | B25: 15
A26: Dominio (prorrateo renovación anual) | B26: 1.25
A27: Subtotal servicios + operativos | B27: =SUM(B19:B26) -> 342.25
A28: Margen de variabilidad (%) | B28: 0.1
A29: Margen de variabilidad (USD) | B29: =B27*B28 -> 34.225
A30: Sueldo de la coordinadora (USD/mes) | B30: 370
A31: Total costos fijos mensuales | B31: =B27+B29+B30 -> 746.475
A33: RIESGO CAMBIARIO E INFLACIÓN (BOLIVIA)
A34: Contexto (referencia, no es un input del cálculo):
A35: • Desde nov. 2011 hasta fines de 2025, el tipo de cambio oficial estuvo fijo en Bs 6,96/USD (venta).
A36: • Entre dic. 2025 y abr. 2026 el BCB inició una flexibilización cambiaria (Valor Referencial del Dólar).
A37: • Sept. 2026: tipo de cambio oficial/referencial ≈ Bs 12,60/USD; paralelo ≈ Bs 12,30-12,50/USD (brecha 1-3%).
A38: • Inflación 2025 (cierre): 20,4% (una de las más altas en décadas, por escasez de dólares).
A39: • Inflación acumulada 2026 (ene-ago, INE): 3,01%; interanual a 12 meses (ago. 2026): 5,02%.
A40: • Proyección BCB para el cierre de 2026: 9,22%. Fuentes: BCB, INE (consultado sept. 2026).
A42: Tipo de cambio de referencia BCB actual (Bs/USD, informativo) | B42: 12.6
A43: Inflación anual proyectada 2026 en Bolivia (BCB, informativo) | B43: 0.0922
A44: Ajuste anual estimado para costos en BOB (alquiler, servicios, sueldo) — supuesto de planificación | B44: 0.1
A45: Nota | B45: La cuota de estante está fijada en USD y se cobra por adelantado para 12 meses; no se ajusta a mitad de ciclo. Conviene revisar el monto de la cuota en cada renovación anual para no perder margen frente a la inflación local.
...

Sheet Punto de equilibrio
A1: Punto de equilibrio — Galería Íntima (peor escenario, base: 148 estantes disponibles)
A3: Estantes necesarios para el equilibrio operativo mensual (solo cuotas, sin Miedos ni suscripciones)
A4: Estantes necesarios | B4: =ROUNDUP(Supuestos!$B$31/Supuestos!$B$9,0) -> 107
A5: Ocupación necesaria (% de los 148 estantes disponibles) | B5: =B4/Supuestos!$B$6 -> 0.72297297
A7: Escenarios en régimen (ocupación estable, sobre 148 estantes disponibles, solo cuotas)
A8: Ocupación (%) | B8: Estantes pagando | C8: Ingreso por cuotas (USD) | D8: Costos totales (USD) | E8: Superávit / Déficit mensual (USD) | F8: ¿Sostenible?
A9: 0.4 | B9: =ROUND(A9*Supuestos!$B$6,0) -> 59 | C9: =B9*Supuestos!$B$9 -> 413 | D9: =Supuestos!$B$31 -> 746.475 | E9: =C9-D9 -> -333.475 | F9: =IF(E9>=0,"Sí","No") -> No
A10: 0.5 | B10: =ROUND(A10*Supuestos!$B$6,0) -> 74 | C10: =B10*Supuestos!$B$9 -> 518 | D10: =Supuestos!$B$31 -> 746.475 | E10: =C10-D10 -> -228.475 | F10: =IF(E10>=0,"Sí","No") -> No
A11: 0.6 | B11: =ROUND(A11*Supuestos!$B$6,0) -> 89 | C11: =B11*Supuestos!$B$9 -> 623 | D11: =Supuestos!$B$31 -> 746.475 | E11: =C11-D11 -> -123.475 | F11: =IF(E11>=0,"Sí","No") -> No
A12: 0.7 | B12: =ROUND(A12*Supuestos!$B$6,0) -> 104 | C12: =B12*Supuestos!$B$9 -> 728 | D12: =Supuestos!$B$31 -> 746.475 | E12: =C12-D12 -> -18.475 | F12: =IF(E12>=0,"Sí","No") -> No
A13: 0.8 | B13: =ROUND(A13*Supuestos!$B$6,0) -> 118 | C13: =B13*Supuestos!$B$9 -> 826 | D13: =Supuestos!$B$31 -> 746.475 | E13: =C13-D13 -> 79.525 | F13: =IF(E13>=0,"Sí","No") -> Sí
A14: 0.9 | B14: =ROUND(A14*Supuestos!$B$6,0) -> 133 | C14: =B14*Supuestos!$B$9 -> 931 | D14: =Supuestos!$B$31 -> 746.475 | E14: =C14-D14 -> 184.525 | F14: =IF(E14>=0,"Sí","No") -> Sí
A15: 1 | B15: =ROUND(A15*Supuestos!$B$6,0) -> 148 | C15: =B15*Supuestos!$B$9 -> 1036 | D15: =Supuestos!$B$31 -> 746.475 | E15: =C15-D15 -> 289.525 | F15: =IF(E15>=0,"Sí","No") -> Sí

Sheet Proyección 24 meses
A1: Proyección mensual — Galería Íntima (24 meses, peor escenario: 148 estantes, solo cuotas)
A3: Mes | B3: 1 | C3: 2 | D3: 3 | E3: 4 | F3: 5 | G3: 6 | H3: 7 | I3: 8 | J3: 9 | K3: 10 | L3: 11 | M3: 12 | N3: 13 | O3: 14 | P3: 15 | Q3: 16 | R3: 17 | S3: 18 | T3: 19 | U3: 20 | V3: 21 | W3: 22 | X3: 23 | Y3: 24
A4: Estantes ocupados (pagando) | B4: =Supuestos!$B$8 -> 148 | C4: =B4 -> 148 | D4: =C4 -> 148 | E4: =D4 -> 148 | F4: =E4 -> 148 | G4: =F4 -> 148 | H4: =G4 -> 148 | I4: =H4 -> 148 | J4: =I4 -> 148 | ... M4: =L4 -> 148 | N4: =ROUND(M4*Supuestos!$B$15,0) -> 126 | O4: =MIN(Supuestos!$B$6,N4+Supuestos!$B$16) -> 131 | P4: =MIN(Supuestos!$B$6,O4+Supuestos!$B$16) -> 136 | Q4: =MIN(Supuestos!$B$6,P4+Supuestos!$B$16) -> 141 | R4: =MIN(Supuestos!$B$6,Q4+Supuestos!$B$16) -> 146 | S4: =MIN(Supuestos!$B$6,R4+Supuestos!$B$16) -> 148 | T4: =MIN(Supuestos!$B$6,S4+Supuestos!$B$16) -> 148 | U4: =MIN(Supuestos!$B$6,T4+Supuestos!$B$16) -> 148 | V4: =MIN(Supuestos!$B$6,U4+Supuestos!$B$16) -> 148 | ... Y4: =MIN(Supuestos!$B$6,X4+Supuestos!$B$16) -> 148
A5: Ingreso por cuotas (USD) | B5: =B4*Supuestos!$B$9 -> 1036 | C5: =C4*Supuestos!$B$9 -> 1036 | D5: =D4*Supuestos!$B$9 -> 1036 | E5: =E4*Supuestos!$B$9 -> 1036 | F5: =F4*Supuestos!$B$9 -> 1036 | G5: =G4*Supuestos!$B$9 -> 1036 | H5: =H4*Supuestos!$B$9 -> 1036 | I5: =I4*Supuestos!$B$9 -> 1036 | ... Y5: =Y4*Supuestos!$B$9 -> 1036
A6: Costos fijos totales (USD, sin inflación) | B6: =Supuestos!$B$31 -> 746.475 | C6: =Supuestos!$B$31 -> 746.475 | D6: =Supuestos!$B$31 -> 746.475 | E6: =Supuestos!$B$31 -> 746.475 | F6: =Supuestos!$B$31 -> 746.475 | G6: =Supuestos!$B$31 -> 746.475 | H6: =Supuestos!$B$31 -> 746.475 | I6: =Supuestos!$B$31 -> 746.475 | ... Y6: =Supuestos!$B$31 -> 746.475
A7: Flujo neto mensual (USD, sin inflación) | B7: =B5-B6 -> 289.525 | C7: =C5-C6 -> 289.525 | D7: =D5-D6 -> 289.525 | E7: =E5-E6 -> 289.525 | F7: =F5-F6 -> 289.525 | G7: =G5-G6 -> 289.525 | H7: =H5-H6 -> 289.525 | I7: =I5-I6 -> 289.525 | ... Y7: =Y5-Y6 -> 289.525
A8: Fondo de reserva acumulado (USD, sin inflación) | B8: =B7 -> 289.525 | C8: =B8+C7 -> 579.05 | D8: =C8+D7 -> 868.575 | E8: =D8+E7 -> 1158.1 | F8: =E8+F7 -> 1447.625 | G8: =F8+G7 -> 1737.15 | H8: =G8+H7 -> 2026.675 | I8: =H8+I7 -> 2316.2 | J8: =I8+J7 -> 2605.725 | ... Y8: =X8+Y7 -> 6528.6
A9: ¿Déficit este mes? (sin inflación) | B9: =IF(B7<0,"SI","NO") -> NO | C9: =IF(C7<0,"SI","NO") -> NO | D9: =IF(D7<0,"SI","NO") -> NO | E9: =IF(E7<0,"SI","NO") -> NO | F9: =IF(F7<0,"SI","NO") -> NO | G9: =IF(G7<0,"SI","NO") -> NO | H9: =IF(H7<0,"SI","NO") -> NO | I9: =IF(I7<0,"SI","NO") -> NO | ... Y9: =IF(Y7<0,"SI","NO") -> NO
A11: SENSIBILIDAD: costos con inflación local desde el mes 13 (año 2)
A12: Costos fijos totales (USD, con inflación desde mes 13) | B12: =B6 -> 746.475 | C12: =C6 -> 746.475 | D12: =D6 -> 746.475 | E12: =E6 -> 746.475 | F12: =F6 -> 746.475 | G12: =G6 -> 746.475 | H12: =H6 -> 746.475 | I12: =I6 -> 746.475 | ... M12: =M6 -> 746.475 | N12: =Supuestos!$B$31*(1+Supuestos!$B$44) -> 821.1225 | O12: =Supuestos!$B$31*(1+Supuestos!$B$44) -> 821.1225 | P12: =Supuestos!$B$31*(1+Supuestos!$B$44) -> 821.1225 | Q12: =Supuestos!$B$31*(1+Supuestos!$B$44) -> 821.1225 | R12: =Supuestos!$B$31*(1+Supuestos!$B$44) -> 821.1225 | S12: =Supuestos!$B$31*(1+Supuestos!$B$44) -> 821.1225 | T12: =Supuestos!$B$31*(1+Supuestos!$B$44) -> 821.1225 | U12: =Supuestos!$B$31*(1+Supuestos!$B$44) -> 821.1225 | ... Y12: =Supuestos!$B$31*(1+Supuestos!$B$44) -> 821.1225
A13: Flujo neto mensual (USD, con inflación desde mes 13) | B13: =B5-B12 -> 289.525 | C13: =C5-C12 -> 289.525 | D13: =D5-D12 -> 289.525 | E13: =E5-E12 -> 289.525 | F13: =F5-F12 -> 289.525 | G13: =G5-G12 -> 289.525 | H13: =H5-H12 -> 289.525 | I13: =I5-I12 -> 289.525 | ... Y13: =Y5-Y12 -> 214.8775
A14: Fondo de reserva acumulado (USD, con inflación desde mes 13) | B14: =B13 -> 289.525 | C14: =B14+C13 -> 579.05 | D14: =C14+D13 -> 868.575 | E14: =D14+E13 -> 1158.1 | F14: =E14+F13 -> 1447.625 | G14: =F14+G13 -> 1737.15 | H14: =G14+H13 -> 2026.675 | I14: =H14+I13 -> 2316.2 | J14: =I14+J13 -> 2605.725 | ... Y14: =X14+Y13 -> 5632.83
A15: ¿Déficit este mes? (con inflación desde mes 13) | B15: =IF(B13<0,"SI","NO") -> NO | C15: =IF(C13<0,"SI","NO") -> NO | D15: =IF(D13<0,"SI","NO") -> NO | E15: =IF(E13<0,"SI","NO") -> NO | F15: =IF(F13<0,"SI","NO") -> NO | G15: =IF(G13<0,"SI","NO") -> NO | H15: =IF(H13<0,"SI","NO") -> NO | I15: =IF(I13<0,"SI","NO") -> NO | ... Y15: =IF(Y13<0,"SI","NO") -> NO
A17: Primer mes con déficit (sin inflación) | B17: =IFERROR(MATCH("SI",B9:Y9,0),"Ninguno (sin déficit en 24 meses)") -> Ninguno (sin déficit en 24 meses)
A18: Primer mes con déficit (con inflación desde mes 13) | B18: =IFERROR(MATCH("SI",B15:Y15,0),"Ninguno (sin déficit en 24 meses)") -> Ninguno (sin déficit en 24 meses)
A19: Fondo de reserva al mes 24 (USD, sin inflación) | B19: =Y8 -> 6528.6
A20: Fondo de reserva al mes 24 (USD, con inflación desde mes 13) | B20: =Y14 -> 5632.83
